Workbook

Sheet Introduction and Instructions
A1: Introduction-Welcome! Please read all information before using
A2: This interactive model is a tool designed to perform a return on investment (ROI) cost-benefit analysis of the financial and social impacts of Restorative Justice Conferencing (RJC) Programs compared to Criminal Justice System (CJS) processes.
A3: Data for this model was gathered through published research, interviews with restorative justice conferencing coordinators, and interviews with staff of the Philadelphia District Attorney's Office.
A4: RJC program costs can vary slightly depending on levels of supportive casework, but costs were generally consistent across programs. CJS process costs can vary dramatically depending on the processes used (i.e. courtroom involvement, incarceration, etc.)
A5: To reflect potential differences in CJS process costs, this model allows users to create three different scenarios (low, medium, and high cost) for calculating ROI outputs that reflect the diversity in CJS (and other) costs.
A6: Instructions-Please read all information before using
A7: 1. This interactive model calculates Impact Return on Investment (IROI) through a cost-benefit-type analysis that compares Criminal Justice System (CJS) Programs with Restorative Justice Conferencing (RJC) Programs. The current data refers to cost and benefit values associated with reasonable estimates for Philadelphia, Pennsylvania, USA. Local values can be substituted to provide more accuracy for other jurisdictions. Current values were obtained from research and interviews; when a range was of values was reasonable, conservative values were selected to minimize any unintentional inflation of ROI values.
A8: 2. Users can adjust values for local accuracy on three sheets: CJS Program Costs, RJC Program Costs, and HP, RP, Community Inputs. Data on the calculations and IROI sheets will automatically update. PLEASE do not change data on any sheets except the CJS Program Costes, RJC Program Costs, and HP, RP, Community Inputs sheets.
A9: 3. Sheets are sequenced in the order in which values feed into the next step. Final values from CJS Program Costs are used in calculating additive RJC Program Costs. These program costs are linked into the "HP, RP, Community Inputs" sheet. All other data in "HP, RP, Community Inputs" was determined through research and interviews (sources provided). The "HP, RP, Community Inputs" sheet provides data for the avoided costs and benefits "calculations" sheet. These values are used in final IROI calculations provided on the "IROI" sheet.
A10: 4. In this model, "HP" refers to harmed parties and "RP" refers to a responsible party. Calculations are based on a PER CASE basis, in which "one case" is one responsible party who is eligible for referral to a RJC program (charged with an RJC eligible offense, acknowledges responsibility, and willing to participate in facilitated accountability practices). One case may have more than one harmed party. The number of harmed parties per case can be adjusted on the "Values and Sources" sheet under "Harmed Party Impacts."
A11: Limitation - to consider
A12: All the costs and benefits reported here have a numerical value associated with them, but it is important to remember that some of the most meaningfrul costs and benefits are qualitative. For example, participants in RJC report feeling more human, heard and valued. For a more detailed analysis and many more stories, see Sered, 2019, Until We Reckon, the New Press.

Sheet CJS Program Costs
A1: Criminal Justice System (CJS) Program Costs
A2: This sheet details the AVERAGE costs associated with Criminal Justice System (CJS) processing PER CASE. One case = one responsible party (RP) eligible to be referred by the DA's office to a Restorative Justice Conferencing (RJC) program.
A3: Cost estimates were gathered through research sources (see notes and sources in this sheet) and through interviews with the Philadelphia District Attorney's Office. DAO staff are working on collecting and reporting more detailed costs; the model can be adjusted as these become available, and also includes an additional row for any additional categories of costs.
A4: To account for both unknowns and diversty in CJS costs (e.g., between jurisdictions), this model provides for three different levels of "sensititivty", that is low, medium, and high cost estimates. Model users can change the "units required" column values and the "percentage of RJC eligible cases in which this CJS cost would be applicable" column values as they see fit to match the typical use of processes for different types of charges. For example, for an assault charge, the use of any pre-trial incarceration days may apply to only a certain percentage of cases. The typical number of pre-trial incarceration days also varies between cases. Users can modify these columns for increased accuracy. Note: Some rows have low, medium, and high percentages set at 100% because those costs typically apply to everyone involved in a CJS process.
A5: Note on nomenclature: The cost estimates below are used to describe costs that the government would typically incur from the time of charging until an eligible case has been "completed" in the CJS system. It is important to note that the cost to "complete a case" does not necessarily lead to the practical matter of "resolving a case" in which harmed parties or those impacted have been satisfied. "Completing a case" in the CJS means that the case has proceeded through CJS processes until the CJS program determines that the process is complete. Completion in this sense may be procedural and have little to do with the needs of those involved or a specific goal (i.e. enacting plans to prevent future harm, demonstrating understanding of impact, taking accountability and doing apologies of action, personal growth demonstrated by positive changes in behavior patterns, applying new skills, public safety, etc.). In CJS, the outcomes and agreement plans are not determined by those most impacted, so it is difficult to determine when and if a case has truly been "resolved."
A6: Note on nomenclature: The commonly used term "Criminal Justice System" (CJS) is used throughout this model to describe criminal policing, prosecution, courts, and corrections processes. An alternative name, "Criminal Legal System," (CLS) was also strongly considered for use because it is increasingly accepted as a more accurate descriptor of the processes in place. The term "Criminal Justice System" was ultimately selected for use because it is more widely recognized at the current time and may help users find and access the material.
A7: Note on fines and fees: Court fees and fines, probation/parole fees, and expungement fees owed by responsible parties were not included in this analysis because there is abundant evidence that there are low rates of payment (on average $28 are collected for every $100 charged in fees and fines for PA public defense clients). These fines and fees were also excluded from calculations describing avoided costs to Responsible Parties when participating in RJC programs. Even though these costs were excluded from this financial analysis, it is important to recognize that the accumulation of these debts is a current long term consequence carried by responsible parties. (https://www.aclupa.org/sites/default/files/field_documents/fines_and_costs_report_updated_march_2021.pdf)
A9: Criminal Justice System (CJS) Costs for RJC Eligible Cases That Go Through CJS to "Case Completion" | M9: Notes | N9: Sources | O9: Second Source
A10: To make this interactive model more accurate, please adjust the values in the columns with down arrows over them. | D10: Do not enter new values in this column. | J10: Do not enter new values in this column. | K10: Do not enter new values in this column. | L10: Do not enter new values in this column.
F11: Percentage of RJC Eligible Cases in which this CJS Cost Would be Applicable | J11: CJS Program Cost Per Case to Completion * Percentage of RJC Eligible Cases in which these CJS Costs Would be Applicable
A12: Criminal Justice System (CJS) Program Costs (1 case=RP eligible referral) | B12: Units Required (see left column for unit, i.e. per day, session, or case) | C12: Cost/unit | D12: CJS Program Cost Per Case to Completion: Units * Cost= | F12: Low | G12: Medium | H12: High | J12: Low CJS Total Costs per Case | K12: Medium CJS Total Costs per Case | L12: High CJS Total Costs per Case
A13: Average $ cost of DAO prosecution operations-processing, coordinating, intake, evidence review, preparation, court appearances, plea bargaining discussions, follow up, etc. PER CASE (Can be broken out into individual rows instead) | B13: 1 | C13: 2000 | D13: =B13*C13 -> 2000 | F13: 1 | G13: 1 | H13: 1 | J13: =D13*F13 -> 2000 | K13: =D13*G13 -> 2000 | L13: =D13*H13 -> 2000 | M13: This number is calculated by dividing the total DAO budget divided by the number of charges issued per year. As such, it represents a mythical average cost per charge, some place between the most expensive and least expensive charges to administer but weighted by the number of each type of charges made. Further, we do not differentiate between low, medium and high, because the average already accounts for the weighting by number of cases - a weighted average that we believe skews low because there are likely many more low-severity/low-cost charges preferred than there are high-severity/high-cost charges. This number could be improved by identifying 1) the percentage of charges eligible for RJC and the costs associated with charges that could be eligible for RJC. | N13: Values provided by Philadelphia DAO. See interview list in report bibliography. Boochever, O adn Meire, C. (2023). Safety in Numbers: Analyzing the Costs and Outcomes in the Philadelphia Criminal Legal System. Harvard Kennedy School. https://drive.google.com/file/d/1QeajLVpWXGZz0ntJIYCFVURWg8iEL_CG/view?usp=drivesdk
A14: Average $ cost Public Defender fees PER CASE | B14: 1 | C14: 80 | D14: =B14*C14 -> 80 | F14: 1 | G14: 1 | H14: 1 | J14: =D14*F14 -> 80 | K14: =D14*G14 -> 80 | L14: =D14*H14 -> 80 | M14: $80 value per case was calculated by dividing Philadelphia Public Defender starting salary by the number of annual caseload number (pg. xii of source). As with the previous row, because we are using an average that is weighted by the number and type of charges defended, there is no way to differentiate low, medium and high percentages of RJC-eligible cases defended. This number could be imporoved by identifying 1) the percentage of charges eligible for RJC and the defense costs associated with RJC-eligible charges. | N14: https://fingfx.thomsonreuters.com/gfx/legaldocs/egvbmodrzpq/RAND_RRA2559-1.pdf; https://whyy.org/articles/philly-public-defenders-staff-pay-raise/
A15: Average $ cost of Court operations-judge, baliff, clerks, maint, continuances, etc. PER CASE | B15: 1 | C15: 6000 | D15: =B15*C15 -> 6000 | F15: 1 | G15: 1 | H15: 1 | J15: =D15*F15 -> 6000 | K15: =D15*G15 -> 6000 | L15: =D15*H15 -> 6000 | M15: $6,000 was estimaged by looking at the history of average court budget per case figures: for FY 2017e-$4559; for FY 2018-$4,835; for FY 2019-$5,906, FY 2020-$9,415; for FY 2021-$12,330. We excluded FY2021-2022 because bottlenecks exacerbated by COVID shutdowns created unusually high per case costs for that year. $6,000 seemed reasonable and conservative estimate for FY 2025. As with the previous row, because we are using an average that is weighted by the number and type of charges incurring court costs, there is no way to differentiate low, medium and high percentages of RJC-eligible cases incurring court costs. This number could be imporoved by identifying 1) the percentage of charges eligible for RJC and the court costs associated with RJC-eligible charges. | N15: Boochever, O adn Meire, C. (2023). Safety in Numbers: Analyzing the Costs and Outcomes in the Philadelphia Criminal Legal System. Harvard Kennedy School. https://drive.google.com/file/d/1QeajLVpWXGZz0ntJIYCFVURWg8iEL_CG/view?usp=drivesdk
A16: Average $ cost pre-trial and/or pre-sentencing incarceration PER DAY/PER PERSON | B16: 7 | C16: 120 | D16: =B16*C16 -> 840 | F16: 0.1 | G16: 0.5 | H16: 1 | J16: =D16*F16 -> 84 | K16: =D16*G16 -> 420 | L16: =D16*H16 -> 840 | M16: Fiscal Year (FY) 2021 and FY 2022 Cost of Incarceration Fee (COIF) for Federal inmates. This is a conservative value, Philadelphia COIF rates are higher. The # of days is a guess; here's a report that identifies factors that affect pre-trial time but does not give an estimate of actual time. https://www.phila.gov/media/20250616114000/May-2025-Full-Public-Report.pdf. | N16: https://www.federalregister.gov/documents/2023/09/22/2023-20585/annual-determination-of-average-cost-of-incarceration-fee-coif; https://www.phila.gov/media/20250616114000/May-2025-Full-Public-Report.pdf
A17: Average $ cost post-sentencing incarceration PER DAY/PER PERSON | B17: 365 | C17: 120 | D17: =B17*C17 -> 43800 | F17: 0.25 | G17: 0.65 | H17: 1 | J17: =D17*F17 -> 10950 | K17: =D17*G17 -> 28470 | L17: =D17*H17 -> 43800 | M17: Used 365 days for one year of incarceration. Fiscal Year (FY) 2021 and FY 2022 Cost of Incarceration Fee (COIF) for Federal inmates. This is a conservative value, Philadelphia COIF rates are higher ($48,000). If an RJC program has a high proportion of people facing felony charges than it would be expected that most participants would face longer terms of incarceration than one year. | N17: https://www.federalregister.gov/documents/2023/09/22/2023-20585/annual-determination-of-average-cost-of-incarceration-fee-coif; If RJ cases are weighted to misdemeanor then low to medium range; if weighted to felony than >1yr (could be more than 150%). Safety in Numbers Analyzing Costs and Outcomes in the Philadelphia Criminal Legal System, Prepared by Oscar Boochever and Chuck Meire, Harvard Kennedy School, April 4, 2023.
A18: Average $ cost Supervision PER CASE | B18: 1 | C18: 746 | D18: =B18*C18 -> 746 | F18: 1 | G18: 1 | H18: 1 | J18: =D18*F18 -> 746 | K18: =D18*G18 -> 746 | L18: =D18*H18 -> 746 | M18: This value was obtained by dividing the 2015 PA budget for supervision ($201,585,365) by the number of people under supervision (270,000). Interviews suggest that this might be between 1000 & 3000 per supervision case annually. As with several previous rows, because we are using an average that is weighted by the number and type of charges supervised, there is no way to differentiate low, medium and high percentages of RJC-eligible cases supervised. This number could be improved by identifying 1) the percentage of charges eligible for RJC and the supervision costs associated with RJC-eligible charges. | N18: https://www.palbfc.gov/Resources/Documents/Reports/509.pdf
A19: DAO CONTRIBUTORS-PLEASE LIST ADDITIONAL COSTS BELOW-List Average $ cost for category PER UNIT (specify unit) | C19: 0 | D19: =B19*C19 -> 0 | J19: =D19*F19 -> 0 | K19: =D19*G19 -> 0 | L19: =D19*H19 -> 0 | M19: Need data from the DA's office on current CJS process for potentially RJC eligible cases. Additional drug testing costs (separate from supervision)?
A20: Total Cost of CJS Proceedings Per Case (for RJC eligible cases) | J20: =SUM(J13:J19) -> 19860 | K20: =SUM(K13:K19) -> 37716 | L20: =SUM(L13:L19) -> 53466 | M20: These are low, medium, and high cost estimates for one case for a person who is RJC eligible, but goes through the traditional CJS process.
J21: Low | K21: Medium | L21: High

Sheet RJC Program Costs
A1: Restorative Justice Conferencing (RJC) Program Costs
A2: Please read the text below for information about Restorative Justice Conferencng (RJC) Program Cost Per Case calculations.
A3: This sheet details an estimate for the AVERAGE costs associated with a Restorative Justice Conferencing (RJC) Program PER CASE. One case = one eligible responsible party (RP) referred to a RJC program by the DA's office.
A4: RJC program cost estimates were gathered through interviews conducted with currently operating local and national RJC diversion programs.
A5: "Resolution" or a "completed case" means that the harmed party (HP) and responsible party (RP) reached agreements and created a specific plan during a RJC and that the RP fulfilled those agreements.
A6: "Incomplete or unresolved cases" involved parts of the RJC process, but did not lead to the fulfillment of agreements and the case was referred back to the Criminal Justice System (CJS).
A7: After RJC intake evaluation, less than 3% of cases would likely be "unresolved" through RJC and return to the CJS after beginning an RJC process. For cases that have partial completion of RJC processes, we have included a table at the bottom of this chart that shows additive costs (parital RJC + CJS) have been accounted for when calculating the AVERAGE cost associated with an RJC program for one eligible case.
A9: Costs for RJC Eligible Cases That Go Through To Resolution/Case Completion | E9: Notes/Logic/Formula | F9: Sources
A10: Restorative Justice Conferencing (RJC) Program Cost (1 case=1 RP eligible referral) | B10: Hours or Units Required | C10: $/hr or $/unit | D10: Cost to Reach Resolution: Hours or Units * Cost=
A11: RJC program initially evaluates whether to take case | B11: 1 | C11: 50 | D11: =B11*C11 -> 50 | E11: $25 matches the hourly cost we heard in interviews, but we raised it to $50 to be conservative because most current initiatives are small and likely understimate the time and cost requirements incurred by larger organizations with larger staffs. We also increased the hourly rate to capture the total cost of employing someone - that is, the additional amount for tax and benefits - approximately 30% for non-profits (although these extras can go as high as 35%). | F11: Values provided by RJC programs. See interview list in report bibliography.
A12: Pre-conferencing preparation with HPs, RP, and supporters | B12: 15 | C12: 50 | D12: =B12*C12 -> 750 | E12: High middle or high end of estimates shared in interviews. | F12: Values provided by RJC programs. See interview list in report bibliography.
A13: Wrap around/support/case work for HPs, RP, and supporters | B13: 15 | C13: 50 | D13: =B13*C13 -> 750 | E13: High middle or high end of estimates shared in interviews. | F13: Values provided by RJC programs. See interview list in report bibliography.
A14: Transporation for participants to onsite activities and conference | B14: 10 | C14: 10 | D14: =B14*C14 -> 100 | E14: High middle or high end of estimates shared in interviews. | F14: Values provided by RJC programs. See interview list in report bibliography.
A15: Conference facilitation, location coordination, and set up | B15: 4 | C15: 50 | D15: =B15*C15 -> 200 | E15: High middle or high end of estimates shared in interviews. | F15: Values provided by RJC programs. See interview list in report bibliography.
A16: Post-conference food/snacks for "breaking bread" together | B16: 1 | C16: 50 | D16: =B16*C16 -> 50 | E16: High middle or high end of estimates shared in interviews. | F16: Values provided by RJC programs. See interview list in report bibliography.
A17: Follow up with participants to monitor/support agreement fulfillment | B17: 10 | C17: 50 | D17: =B17*C17 -> 500 | E17: High middle or high end of estimates shared in interviews. | F17: Values provided by RJC programs. See interview list in report bibliography.
A18: Follow up services and activities for HP and RP-community support and integration, celebration of agreement fulfillment | B18: 10 | C18: 50 | D18: =B18*C18 -> 500 | E18: High middle or high end of estimates shared in interviews. | F18: Values provided by RJC programs. See interview list in report bibliography.
A19: RJC program facilities and adminstrative overhead costs | B19: 1 | C19: 300 | D19: =B19*C19 -> 300 | E19: Facilities costs, insurance, office supplies, etc. | F19: Values provided by RJC programs. See interview list in report bibliography.
A20: RJC progam non-faciliation staff (leadership, financial, data analysis) | B20: 1 | C20: 250 | D20: =B20*C20 -> 250 | E20: This is the cost of the program management and coordination on a per case basis estimated on the basis of two admin staff in a program handling 1,000 cases/year (average salary of $65,000 and a taxes and benefits overhead of 30%). | F20: Values provided by RJC programs. See interview list in report bibliography.
A21: RJC program ongoing training and professional development | B21: 1 | C21: 150 | D21: =B21*C21 -> 150 | F21: Values provided by RJC programs. See interview list in report bibliography.
A22: Projected CJS overhead to process a case through RJC | B22: 1 | C22: 1000 | D22: =B22*C22 -> 1000 | E22: Present state includes: o FTE Juvenile Victim Witness Coordinator o FTE Director of Family and Youth Services o FTE Adult Restorative Justice Supervisor o PTE Juvenile Diversion Supervisor (20%) o PTE Adult Diversion Supervisor (5%) o PTE Juvenile Paralegal (10%) o PTE Data Analyst (10%) o PTE Researcher (10%) Future state may include: o FTE ADAs and RJ personnel that look at case between arrest/charging and preliminary hearing o FTE Adult Restorative Justice Victim Witness Coordinator o FTE Restorative Justice Paralegal o PTE Data Analyst (50%) o PTE Researcher (50%) NOTE: we adjusted all amounts to reflect the ideas that this staff apportionment could handle about 1000 cases. | F22: From Personal Communication with DAO staffers on 1/24/25. Estimated value. DA office is working to improve the estimate.
A23: Cost Total for Cases that go to Resoulution via RJC | D23: =SUM(D11:D22) -> 4600 | E23: This is a sum of the values above it in this section. | F23: This estimate is for baseline RJC. For RJC that includes more thorough wrap around supports like job placement, connection with healthcare providers, emergency shelter, etc (and potentially better long term outcomes) the costs woulud be closer to $7000/case accroding to practioner interview notes.
A24: Costs of RJC Eligible Cases that only go through Pre-Conferecing process and then are Referred back to CJS (Preconferncing RJC Process Costs Only + CJS Process Costs)
A25: RJC program initially evaluates whether to take case | B25: 1 | C25: 50 | D25: =B25*C25 -> 50
A26: Pre-conferencing preparation with HPs, RP, and supporters | B26: 15 | C26: 50 | D26: =B26*C26 -> 750
A27: RJC program facilities and adminstrative overhead costs | B27: 1 | C27: 100 | D27: =B27*C27 -> 100 | E27: This value is only $100 to reflect that doing pre-conferencing only is a fraction of the portion of the overhead.
A28: Total Average $ Cost of CJS Proceedings (from CJS sheet) | B28: 1 | C28: ='CJS Program Costs'!K20 -> 37716 | D28: =B28*C28 -> 37716 | E28: The value for estimated CJS costs is from the "medium" percentage of total costs for a CJS processed case on the sheet labeled CJS program costs.
A29: RJC + CJS Cost Total for Cases that go through Preconferencing only, do not proceed to conferncing | D29: =SUM(D25:D28) -> 38616 | E29: This is a sum of the values above it in this section.
A30: Costs of RJC Eligible Cases that go through Conferencing Process but do not result in agreements or agreeemnt fulfillment and are then referred back to CJS (RJC Process Costs + CJS Process Costs)
A31: RJC cases that are fully conferenced, but not resolved and return to CJS | B31: 1 | C31: =D23 -> 4600 | D31: =B31*C31 -> 4600
A32: Total Average $ Cost of CJS Proceedings (from CJS sheet) | B32: 1 | C32: ='CJS Program Costs'!K20 -> 37716 | D32: =B32*C32 -> 37716 | E32: The value for estimated CJS costs is from the "medium" of total costs for a CJS processed case on the sheet labeled CJS program costs.
A33: Cost Total for Cases that go through RJ Conferencing but do not result in agreeement or agreement fulfillment (essentially RJC and CJS costs combined) | D33: =SUM(D31:D32) -> 42316 | E33: This is a sum of the values above it in this section.
A35: Calculating RJC Program Average Cost Per Case
B36: Cost for cases that go to resolution through RJC program (full RJC costs only) | C36: Cost for cases that go through pre-conferencing only, do not proceed, and go back to CJS, (partial RJC Costs + CJS Costs) | D36: Cost for cases that go through RJC process, but not resolved and back to CJS, (full RJC + CJS Costs)
A37: Program costs per case | B37: =D23 -> 4600 | C37: =D29 -> 38616 | D37: =D33 -> 42316 | E37: These values are from the calculations in the tables above.
A38: To make this interactive model more accurate, please adjust the PERCENTAGE VALUES ONLY in the columns with down arrows over them. The three values must total exactly 100%
A39: % of cases that this condition applies to (assuming 100 case sample) | B39: 0.97 | C39: 0.025 | D39: 0.005 | E39: RJC practioners shared completion rates of 96-99%. | F39: Values provided by RJC programs. See interview list in report bibliography.
A40: Cost per type of case outcome * 100 cases * frequence of occurence | B40: =B37*B39*100 -> 446200 | C40: =C37*C39*100 -> 96540 | D40: =D37*D39*100 -> 21158 | E40: Program costs per case * Percent this condition applies to * 100 cases
A42: Total RJC Costs per 100 cases sample | B42: =SUM(B40:D40) -> 563898 | E42: Sum of costs from line above for 100 cases that are a mixture of RJC only and partial RJC + CJS
A43: RJC Average Cost Per Case | B43: =B42/100 -> 5638.98 | E43: Total costs for 100 cases divided by 100

Sheet HP, RP, Community Inputs
A1: HP, RP, and Community Inputs: Values and References/Sources
A2: Please read the text below for information about this sheet.
A3: All data for the "calculations" and "IROI" sheets are sourced from this sheet. Values are reasonable estimates based on the research sources and/or interviews provided.
A4: The number of Harmed Parties (HP) can be modified as needed on this sheet in the section under "Harmed Party Impacts Per Case."
B5: Value | C5: Measure | D5: Range | E5: Notes | F5: Sources & Additional Notes
A6: To make this interactive model more accurate, ONLY adjust the values in the rows with the blue arrows pointing to them. | B6: Average CJS Program Costs per Case
B7: ='CJS Program Costs'!J20 -> 19860 | C7: Low Value | E7: See sheet labeled "CJS Program Costs."
B8: ='CJS Program Costs'!K20 -> 37716 | C8: Medium Value | E8: See sheet labeled "CJS Program Costs."
B9: ='CJS Program Costs'!L20 -> 53466 | C9: High Value | E9: See sheet labeled "CJS Program Costs."
B11: Average RJC Program Costs per Case
B12: ='RJC Program Costs'!B43 -> 5638.98 | C12: Costs calculated by interviewing current RJC programs. | D12: $3000-$6000 | E12: See sheet labeled "RJC Program Costs."
B14: Harmed Party Impacts Per Case
B15: 2 | C15: Average number of harmed parties per case | D15: 0-10 | E15: Two HP is conservative. All RJC practioners interviewed shared that in addition to the directly harmed party, those closest to them (spouse, child, parent) are also harmed during events that impact HP safety and welfare. | F15: Values provided by RJC programs. See interview list in report bibliography.
B17: HP Restitution Recieved vs. CJS Restitution Received
B18: 1500 | C18: Average restitution needed per harmed party | D18: $0-10,000 | E18: $1500 over and above what the victim fund might pay for eligible costs. (One interviewee suggested $3000, and another $1000.) | F18: Additional values provided by RJC programs. See interview list in report bibliography. https://www.aclupa.org/app/uploads/2021/03/fines_and_costs_report_updated_march_2021.pdf
B19: 0.23 | C19: Percent increase in restitution payments made when RP goes through RJC vs. CJS | D19: 0.23 | E19: RP in RJC programs are more likely to pay restitution (89%) than those sentenced through CJS (66%), a 23% increase. | F19: Domínguez, P., & Raphael, S. (2015). The role of the cost-of-crime literature in bridging the gap between social science research and policy making: Potentials and limitations. Criminology & Public Policy, 14(4), 589-632. https://doi.org/10.1111/1745-9133.12148
B21: HP Reduced Time in Court and Legal Proceedings
B22: 250 | C22: Avoided Cost-Transporation Expenses | D22: $0-35,000 | E22: Funds used to reimburse an individual who incurs expenses traveling to or from counseling or to attend a criminal justice proceeding, and for efforts that aid the investigation. RJC programs typically include transporation for participants in their program costs. Estimated expenses as valued by PA Victim Compensation Funds value ($35,000 maximum). Adult diversion estimate provided by RJC practioners (see interview notes). | F22: https://www.pa.gov/content/dam/copapwp-pagov/en/pcv/documents/for-victims/documents/transportation%20expenses.pdf
B23: 5000 | C23: Avoided Cost-Loss of Income | D23: $0-15,000 | E23: Funds used to cover losses to do attending court, counseling, and efforts that aid the investigation. Estimated expenses as valued by PA Victim Compensation Funds ($15,000 maximum). $7,500 was chosen as a reasonable estimate to account for HP variety of earnings and situations. HP with salaried jobs and benefits may be able to take time without direct compensation loss. HP involved in hourly or gig work will have more substantial impacts and lost working opportunties because of time needed to attend legal proceedings. Depending on the jurisdiction, there might be a fund to cover some of these expenses. A portion of this HP benefit might in fact be a community benefit if there is a fund available and HP go through the process to receive those benefits. | F23: https://www.pa.gov/content/dam/copapwp-pagov/en/pcv/documents/victims-compensation/loss%20of%20earnings%20flyer.pdf
B24: 0.8 | C24: Percent difference in time and expense lost due to attending legal proceedings. | D24: 0-100% | E24: i.e. # of days and trips needed to participate in RJC compared to # of days and trips to participate in CJS. RJC scheduling is streamlined to those directly invovled and flexible to accomodate scheduling needs. CJS court appearances are often stayed because a critical participant does not show, rescheduling after showing up for scheduled appointments adds to total missed work hours for HP. | F24: Need DAO staff input for this data point, estimate based on interviews.
B26: Responsible Party Impacts Per Case
B27: Increase in RP one year wage earnings from GED completion and/or continuing education agreements in RJC program
B28: 8840 | C28: Average increase in one year earnings when GED/high school diploma obtained OR continuing education through RJC agreements. | D28: $5,252-27,920 | E28: $8,840 with HS diploma/GED. National averages ($953/week with some college, $852/week with HS diploma). Weekly difference of $101. One year difference ($101*52) equals additional $5,252 with some college/training. High end estimated is calculated by looking at salaries of graduates from short term continuing education program specializing in IT skills and subtracting minimum wage ($43,000-15,080). | F28: https://www.bls.gov/careeroutlook/2023/data-on-display/education-pays.htm
B29: 0.1 | C29: Percent obtaining GED/continuing education due to RJC program agreements | E29: Estimate | F29: See RJC practioner interview notes. This could be improved by surveying more practioners.
B31: Avoided RP expungement related earnings reductions
B32: 3016 | C32: Avoided decrease in earnings due to expungment instead of having a record | D32: 16-52% decrease | E32: 20% reduction was chosen to be convservative in the wide range between 16% for misdeamenor convictions and 52% for felony convictions. Assuming a yearly federal minimum wage salary of $15,080, a 20% reduction because of having a criminal record would be a loss of $3,016 dollars. This is conservative estimate of the avoided cost. | F32: https://www.brennancenter.org/our-work/research-reports/conviction-imprisonment-and-lost-earnings-how-involvement-criminal#:~:text=People%20convicted%20of%20a%20felony,an%20average%20of%2016%20percent.
B33: 0.8 | C33: Percent increase in expungement rate due to RJC program over CJS program | D33: 20-100% | E33: Conviction relief/expungement follow through below 20% is the norm after CJS (pg. 524). RJC programs have 95-100% expungement. | F33: Chien, Colleen V. “America’s Paper Prisons: The Second Chance Gap.” SSRN Scholarly Paper. Rochester, NY: Social Science Research Network, December 16, 2020. https://doi.org/10.2139/ssrn.3265335.
B35: RP earnings because not incarcerated
B36: 15080 | C36: One year earnings due to RJC program vs. average one year of being incarcerated (RJ practioners noted potential sentences from 3-24 months, with many in the 11-24 month range) | E36: Federal minimum wage is $15,080 for a full time worker. Incarceration sentences vary greatly depending on type of charge and whether a felony or misdemeanor. The average sentencing for most types of charges was still greather than 12 months. The cost of incarceration would be avoided through RJC programs. | F36: https://www.dol.gov/general/topic/wages/minimumwage https://www.ussc.gov/about/annual-report-2023?utm_source=chatgpt.com#_ftn10 https://www.prisonpolicy.org/global/2024.html#:~:text=As%20a%20result%2C%20incarceration%20has,and%20just%20in%20the%20world
B37: ='CJS Program Costs'!F17 -> 0.25 | C37: LOW VALUE-Percent of RP who would avoid one year incarceration sentences because of completion of RJC program | E37: The value in this row comes from the tab "CJS Program Costs" and the line "Average $ cost post-sentencing incarceration PER DAY/PER PERSON"
B38: ='CJS Program Costs'!G17 -> 0.65 | C38: MEDIUM VALUE-Percent of RP who would avoid one year incarceration sentences because of completion of RJC program | E38: The value in this row comes from the tab "CJS Program Costs" and the line "Average $ cost post-sentencing incarceration PER DAY/PER PERSON"
B39: ='CJS Program Costs'!H17 -> 1 | C39: HIGH VALUE-Percent of RP who would avoid one year incarceration sentences because of completion of RJC program | E39: The value in this row comes from the tab "CJS Program Costs" and the line "Average $ cost post-sentencing incarceration PER DAY/PER PERSON"
B41: Community Impacts Per Case-One Year
B42: Community Service Hours Benefit
B43: 40 | C43: Average hours of community service per case | D43: 20-40 | E43: When community service is part of agreements, it's typically around 40 hours. Note that we assume only 15% of cases include community service. | F43: See RJC practioner interview notes.
B44: 15 | C44: Dollar value of community service/hour | D44: $7.25-15 | E44: Much higher estimates ($31/hour in PA) are currently accepted as the dollar value of community service, but $15/hour was a more conservative estimate to reflect earnings closer to the minimum wage. | F44: https://independentsector.org/wp-content/uploads/2024/04/is-vovt-report-all-years_v2-1.pdf
B45: 0.15 | C45: Percentage of RP that are assigned and complete community service as part of RJC agreements | D45: 0-100% | E45: Philadelphia Adult diversion RJC practioners shared that community service is less common for adult than for youth RJ agreements. | F45: See RJ practioner interview notes.
B47: Tax Revenue Benefit Value Due to RP Increased Employment and Earnings
B48: 15080 | C48: Avoided lost one year taxable earnings due to RJC program vs. one year of being incarcerated (federal minimum wage). | D48: $0-$60,000 | E48: Federal minimum wage one year salary. | F48: https://www.dol.gov/general/topic/wages/minimumwage
B49: 0.1675 | C49: Conservative tax rate of 16.75% (Federal-10%, PA state tax-3%, Phila city wage tax-3.75%) | D49: 5-25% tax rate | E49: https://www.irs.gov/filing/federal-income-tax-rates-and-brackets | F49: https://www.pa.gov/agencies/revenue/resources/tax-rates.html; https://www.phila.gov/services/payments-assistance-taxes/taxes/business-taxes/business-taxes-by-type/wage-tax-employers/
...

Sheet Cost and Benefit Calculations
A1: Calculations - Please do NOT change any values on this page!
A2: Metric | B2: Value | C2: Formula/Logic | D2: Notes
A4: Harmed Party (HP) Value Impacts Total
A5: Number of HP per case | B5: ='HP, RP, Community Inputs'!B15 -> 2 | C5: Value from "Inputs" sheet
A7: Total HP Restituion Received vs. CJS Restitution Received
A8: Average restitution needed per harmed party | B8: ='HP, RP, Community Inputs'!B18 -> 1500 | D8: Restitution does not include losses that would be paid by PA Victim Compensation Fund (to avoid duplication of benefit).
A9: % increase in RJC vs. CJS program restituion payments | B9: ='HP, RP, Community Inputs'!B19 -> 0.23
A10: Total HP Restituion Received vs. CJS Restitution Received Value | B10: =B5*B8*B9 -> 690 | C10: Number of HP per case*average restituion needed per harmed party*% increase in restitution payments
A12: HP Reduced Time in Court and Legal Proceedings
A13: Avoided Cost-Transporation Expenses | B13: ='HP, RP, Community Inputs'!B22 -> 250
A14: Avoided Cost-Loss of Income | B14: ='HP, RP, Community Inputs'!B23 -> 5000
A15: Percent difference in time and expense lost due to attending legal proceedings. | B15: ='HP, RP, Community Inputs'!B24 -> 0.8
A16: Total HP Reduced Time in Court and Legal Proceedings | B16: =B5*((B13+B14)*B15) -> 8400 | C16: Number of HP per case * ((avoided transportation expenses + avoided loss of income)*% difference in time and expense lost due to attending legal proceedings)
A18: Harmed Party (HP) Value Impacts Total | B18: =B10+B16 -> 9090 | C18: This is the sum of the benefits and avoided costs in this section.
A20: Responsible Party Value Impacts Total
A21: Increase in RP one year wage earnings from GED completion and/or continuing education agreements in RJC program
A22: Average increase in one year earnings when GED/high school diploma obtained OR continuing ed through RJC agreements. | B22: ='HP, RP, Community Inputs'!B28 -> 8840
A23: Percent obtaining GED due to RJC program agreements | B23: ='HP, RP, Community Inputs'!B29 -> 0.1
A24: Increase in RP one year wage earnings from GED completion and/or continuing education agreements in RJC program | B24: =B22*B23 -> 884 | C24: Avg. increase in one year earnings with GED/continuing ed completion * percent of RJC participants obtaining GED/continuing ed due to program agreements
A26: Avoided RP expungement related earnings reductions
A27: Avoided decrease in earnings due to expungment instead of having a record | B27: ='HP, RP, Community Inputs'!B32 -> 3016
A28: Percent increase in expungement follow through rate due to RJC program over CJS program | B28: ='HP, RP, Community Inputs'!B33 -> 0.8
A29: Avoided RP expungement related earnings reductions | B29: =B27*B28 -> 2412.8 | C29: Avoided decrease in earnings due to expungement * percent increase in expungement follow through rate from RJC program
A31: Avoided RP lost earnings
A32: Avoided loss of one year earnings due to RJC program vs. one year of being incarcerated | B32: ='HP, RP, Community Inputs'!B36 -> 15080
A33: LOW VALUE-Percent of RP who would avoid one year incarceration sentences because of completion of RJC program | B33: ='HP, RP, Community Inputs'!B37 -> 0.25
A34: MEDIUM VALUE-Percent of RP who would avoid one year incarceration sentences because of completion of RJC program | B34: ='HP, RP, Community Inputs'!B38 -> 0.65
A35: HIGH VALUE-Percent of RP who would avoid one year incarceration sentences because of completion of RJC program | B35: ='HP, RP, Community Inputs'!B39 -> 1
A36: Low Incarceration Rate Avoided RP lost earnings | B36: =B32*B33 -> 3770 | C36: Avoided loss of one year earnings * percent of RP who would avoid one year incarceration sentences because of RJC program
A37: Medium Incarceration Rate Avoided RP lost earnings | B37: =B32*B34 -> 9802 | C37: Avoided loss of one year earnings * percent of RP who would avoid one year incarceration sentences because of RJC program
A38: High Incarceration Rate Avoided RP lost earnings | B38: =B32*B35 -> 15080 | C38: Avoided loss of one year earnings * percent of RP who would avoid one year incarceration sentences because of RJC program
A40: Low Incarceration Rate-Responsible Party Value Impacts Total | B40: =B36+B29+B24 -> 7066.8 | C40: This is the sum of the benefits and avoided costs in this section.
A41: Medium Incarceration Rate-Responsible Party Value Impacts Total | B41: =B37+B29+B24 -> 13098.8 | C41: This is the sum of the benefits and avoided costs in this section.
A42: High Incarceration Rate-Responsible Party Value Impacts Total | B42: =B24+B29+B38 -> 18376.8 | C42: This is the sum of the benefits and avoided costs in this section.
A44: Community Value Impacts Total
A45: Community Service Hours Benefit
A46: Average hours of community service per case | B46: ='HP, RP, Community Inputs'!B43 -> 40
A47: Dollar value of community service/hour | B47: ='HP, RP, Community Inputs'!B44 -> 15
A48: Percentage of RP that complete community service hours as part of RJC agreements | B48: ='HP, RP, Community Inputs'!B45 -> 0.15
A49: Community Service Hours Benefit Value | B49: =B46*B47*B48 -> 90 | C49: Average hours of community service * Dollar value of community service/hour* % of RP that complete community service hours as part of agreements
...

Sheet Impact ROI
A1: Impact Return on Investment (IROI) | C1: Calculations - Please do NOT change any values on this page.
A2: This page provides the impact return on investment (IROI) for RJC Diversion Programs. The results are posted immediately below in large font.
A3: The result number means that for every dollar invested in a RJC program, the IROI value is the benefit earned (i.e. investing $1 in RJC provides $4 in benefits because of program savings, benefits to stakeholders, and avoided costs.)
A4: Inputs and a step-by-step explanation of the IROI calculations are listed below.
A5: IROI Outputs
A6: Sensitivity Analysis
A7: =B35 -> 6.1412718 | B7: Low
A8: =B36 -> 11.031653 | B8: Med
A9: =B37 -> 15.336432 | B9: High
A11: Inputs Per Case
A12: Category | B12: Value | C12: Notes
A13: Criminal Justice System (CJS) Program Cost LOW | B13: ='HP, RP, Community Inputs'!B7 -> 19860 | C13: From "CJS Program Costs" sheet
A14: Criminal Justice System (CJS) Program Cost MEDIUM | B14: ='HP, RP, Community Inputs'!B8 -> 37716 | C14: From "CJS Program Costs" sheet
A15: Criminal Justice System (CJS) Program Cost HIGH | B15: ='HP, RP, Community Inputs'!B9 -> 53466 | C15: From "CJS Program Costs" sheet
A17: Restorative Justice Conferencing (RJC) Program Cost | B17: ='HP, RP, Community Inputs'!B12 -> 5638.98 | C17: From "RJC Program Costs" sheet
A19: RJC vs. CJS Program Price Differences (Avoided cost by using RJC average cost instead of CJS)
A20: LOW Cost CJS Scenario Minus RJC Cost | B20: =B13-B17 -> 14221.02 | C20: Price difference in programs (CJS cost - RJC cost)
A21: MEDIUM Cost CJS Scenario Minus RJC Cost | B21: =B14-B17 -> 32077.02 | C21: Price difference in programs (CJS cost - RJC cost)
A22: HIGH Cost CJS Scenario Minus RJC Cost | B22: =B15-B17 -> 47827.02 | C22: Price difference in programs (CJS cost - RJC cost)
A24: LOW Total RJC Benefits and Avoided Costs-Low Incarceration Rate and Low CJS Cost | B24: ='Cost and Benefit Calculations'!B78 -> 20409.489 | C24: From "Cost and Benefit Calculations" sheet
A25: MEDIUM Total RJC Benefits and Avoided Costs-Medium Incarceration Rate and Medium CJS Cost | B25: ='Cost and Benefit Calculations'!B79 -> 30130.249 | C25: From "Cost and Benefit Calculations" sheet
A26: HIGH Total RJC Benefits and Avoided Costs-High Incarceration Rate and High CJS Cost | B26: ='Cost and Benefit Calculations'!B80 -> 38654.814 | C26: From "Cost and Benefit Calculations" sheet
A29: OVERALL BENEFIT: Price difference in programs (program savings) PLUS HP, community, and RP benefits and avoided costs
A30: LOW Cost CJS vs. RJC Price Difference (program savings) PLUS HP, community, and RP benefits and avoided costs calculated using low incarceration rates and low CJS costs | B30: =B20+B24 -> 34630.509 | C30: Added price difference from applicable row immediately above to applicable row from Benefits and Avoided Costs.
A31: MEDIUM Cost CJS vs. RJC Price Difference (program savings) PLUS HP, community, and RP benefits and avoided costs calculated using medium incarceration rates and medium CJS costs | B31: =B21+B25 -> 62207.269 | C31: Added price difference from applicable row immediately above to applicable row from Benefits and Avoided Costs.
A32: HIGH Cost CJS vs. RJC Price Difference (program savings) PLUS HP, community, and RP benefits and avoided costs calculated using high incarceration rates and high CJS costs | B32: =B22+B26 -> 86481.834 | C32: Added price difference from applicable row immediately above to applicable row from Benefits and Avoided Costs.
A34: IROI: TOTAL BENEFITS divided by the cost of the investment in RJC
A35: IROI SENSITIVITY - LOW | B35: =B30/B17 -> 6.1412718 | C35: Divided OVERALL BENEFIT from applicable row in section directly above by the cost of a RJC Program.
A36: IROI SENSITIVITY - MEDIUM | B36: =B31/B17 -> 11.031653 | C36: Divided OVERALL BENEFIT from applicable row in section directly above by the cost of a RJC Program.
A37: IROI SENSITIVITY - HIGH | B37: =B32/B17 -> 15.336432 | C37: Divided OVERALL BENEFIT from applicable row in section directly above by the cost of a RJC Program.
A39: IROI - BY CATEGORY: Program Savings (MEDIUM); Harmed Party Benefits; Responsible Party Benefis; Community Benefits (1 year)
A40: IROI Progam Savings (Medium Sensitivity) | B40: =B21/B17 -> 5.6884437 | C40: Medium sensitivity Program Savings divided by cost of investment in RJC
A41: IROI Harmed Party Benefits | B41: ='Cost and Benefit Calculations'!B18/'Impact ROI'!B17 -> 1.6119937 | C41: HP Benefits from Cost and Benefit Calculations Sheet divided by cost of investment in RJC
A42: IROI Responsible Party Benefits | B42: ='Cost and Benefit Calculations'!B41/'Impact ROI'!B17 -> 2.3229024 | C42: Medium RP Benefits from Cost and Benefit Calculations Sheet divided by cost of investment in RJC
A43: IROI Community Benefits | B43: ='Cost and Benefit Calculations'!B75/'Impact ROI'!B17 -> 1.408313 | C43: Medium Community Benefits (1 year) from Cost and Benefits Calculations Sheet divided by cost of investment in RJC
